Workbook

Sheet Sheet1
A1: long | B1: lat | C1: yr | D1: mon | E1: day | F1: temp | G1: rh | H1: ws | I1: prec
A2: -118.22 | B2: 34.44 | C2: 2025 | D2: 1 | E2: 1 | F2: 15.083 | G2: 31.64 | H2: 17 | I2: 0
A3: -118.22 | B3: 34.44 | C3: 2025 | D3: 1 | E3: 1 | F3: 13.383 | G3: 37.57 | H3: 13 | I3: 0
A4: -118.22 | B4: 34.44 | C4: 2025 | D4: 1 | E4: 1 | F4: 11.067 | G4: 42.63 | H4: 10 | I4: 0
A5: -118.22 | B5: 34.44 | C5: 2025 | D5: 1 | E5: 1 | F5: 10.161 | G5: 41.72 | H5: 9 | I5: 0
A6: -118.22 | B6: 34.44 | C6: 2025 | D6: 1 | E6: 1 | F6: 10.433 | G6: 40.42 | H6: 12 | I6: 0
A7: -118.22 | B7: 34.44 | C7: 2025 | D7: 1 | E7: 1 | F7: 10.694 | G7: 39.47 | H7: 12 | I7: 0
A8: -118.22 | B8: 34.44 | C8: 2025 | D8: 1 | E8: 1 | F8: 8.417 | G8: 39.34 | H8: 12 | I8: 0
A9: -118.22 | B9: 34.44 | C9: 2025 | D9: 1 | E9: 1 | F9: 9.3 | G9: 42.64 | H9: 15 | I9: 0
A10: -118.22 | B10: 34.44 | C10: 2025 | D10: 1 | E10: 1 | F10: 8.661 | G10: 34.42 | H10: 12 | I10: 0
A11: -118.22 | B11: 34.44 | C11: 2025 | D11: 1 | E11: 1 | F11: 8.094 | G11: 37.91 | H11: 12 | I11: 0
A12: -118.22 | B12: 34.44 | C12: 2025 | D12: 1 | E12: 1 | F12: 8.844 | G12: 40.98 | H12: 14 | I12: 0
A13: -118.22 | B13: 34.44 | C13: 2025 | D13: 1 | E13: 1 | F13: 7.939 | G13: 35.33 | H13: 14 | I13: 0
... A745: -118.22 | B745: 34.44 | C745: 2025 | D745: 1 | E745: 31 | F745: 16.35 | G745: 33.77 | H745: 11 | I745: 0

Sheet Sayfa1
B1: hour | C1: Temperature_K | D1: WindU_mps | E1: WindV_mps | F1: prec(m) | G1: prec(mm)
B2: 0 | C2: 292.82422 | D2: -0.033554077 | E2: -0.097000122 | F2: 0 | G2: =Sayfa1!F2*1000 -> 0
B3: 0.041666667 | C3: 291.79553 | D3: 0.27870178 | E3: 0.04359436 | F3: 0 | G3: =Sayfa1!F3*1000 -> 0
B4: 0.083333333 | C4: 291.43408 | D4: -0.02154541 | E4: -0.63194275 | F4: 0 | G4: =Sayfa1!F4*1000 -> 0
B5: 0.125 | C5: 291.47937 | D5: -0.6962738 | E5: -1.2653351 | F5: 0 | G5: =Sayfa1!F5*1000 -> 0
B6: 0.16666667 | C6: 291.27344 | D6: -1.1206818 | E6: -2.0147095 | F6: 0 | G6: =Sayfa1!F6*1000 -> 0
B7: 0.20833333 | C7: 291.0719 | D7: -1.0183563 | E7: -2.3303528 | F7: 0 | G7: =Sayfa1!F7*1000 -> 0
B8: 0.25 | C8: 290.93933 | D8: -0.97848511 | E8: -2.3766022 | F8: 0 | G8: =Sayfa1!F8*1000 -> 0
B9: 0.29166667 | C9: 290.79517 | D9: -1.0464935 | E9: -2.3826752 | F9: 0 | G9: =Sayfa1!F9*1000 -> 0
B10: 0.33333333 | C10: 290.72534 | D10: -0.97869873 | E10: -2.4031982 | F10: 0 | G10: =Sayfa1!F10*1000 -> 0
B11: 0.375 | C11: 290.85669 | D11: -0.8543396 | E11: -2.3558197 | F11: 0 | G11: =Sayfa1!F11*1000 -> 0
B12: 0.41666667 | C12: 289.88574 | D12: -0.88365173 | E12: -2.4517517 | F12: 0 | G12: =Sayfa1!F12*1000 -> 0
B13: 0.45833333 | C13: 289.91138 | D13: -0.77679443 | E13: -2.3674316 | F13: 0 | G13: =Sayfa1!F13*1000 -> 0
... B745: 0.95833333 | C745: 289.63037 | D745: 0.79222107 | E745: 1.6295776 | F745: 0 | G745: =Sayfa1!F745*1000 -> 0

Sheet SE677
A1: Column1 | B1: Column2 | C1: Column3 | D1: Column4 | E1: Column5 | F1: Column6 | G1: Column7 | H1: Column8
A2: Dec 31, 4:00 pm | B2: 16 | C2: -2 | D2: 30 | F2: NE | G2: 10 | H2: 744
A3: Dec 31, 5:00 pm | B3: 14 | C3: -1 | D3: 35 | F3: SE | G3: 8 | H3: 743
A4: Dec 31, 6:00 pm | B4: 13 | C4: -1 | D4: 38 | F4: ESE | G4: 7 | H4: 742
A5: Dec 31, 7:00 pm | B5: 11 | C5: -2 | D5: 39 | F5: ENE | G5: 6 | H5: 741
A6: Dec 31, 8:00 pm | B6: 10 | C6: -3 | D6: 41 | E6: 9 | F6: ENE | G6: 6 | H6: 740
A7: Dec 31, 9:00 pm | B7: 8 | C7: -4 | D7: 40 | E7: 8 | F7: NE | G7: 5 | H7: 739
A8: Dec 31, 10:00 pm | B8: 9 | C8: -4 | D8: 38 | F8: ENE | G8: 5 | H8: 738
A9: Dec 31, 11:00 pm | B9: 9 | C9: -4 | D9: 40 | F9: NE | G9: 3 | H9: 737
A10: Jan 1, 12:00 am | B10: 11 | C10: -4 | D10: 35 | F10: ENE | G10: 7 | H10: 736
A11: Jan 1, 1:00 am | B11: 11 | C11: -5 | D11: 34 | F11: ENE | G11: 5 | H11: 735
A12: Jan 1, 2:00 am | B12: 9 | C12: -5 | D12: 35 | E12: 9 | F12: ENE | G12: 5 | H12: 734
A13: Jan 1, 3:00 am | B13: 7 | C13: -6 | D13: 40 | F13: N | G13: 2 | H13: 733
A14: Jan 1, 4:00 am | B14: 9 | C14: -5 | D14: 37 | E14: 8 | F14: E | G14: 5 | H14: 732
A15: Jan 1, 5:00 am | B15: 7 | C15: -8 | D15: 34 | E15: 5 | F15: ENE | G15: 11 | H15: 731
A16: Jan 1, 6:00 am | B16: 6 | C16: -8 | D16: 37 | E16: 5 | F16: ENE | G16: 7 | H16: 730
A17: Jan 1, 7:00 am | B17: 8 | C17: -6 | D17: 39 | E17: 7 | F17: ENE | G17: 6 | H17: 729
A18: Jan 1, 8:00 am | B18: 11 | C18: -4 | D18: 35 | F18: E | G18: 9 | H18: 728
A19: Jan 1, 9:00 am | B19: 12 | C19: -3 | D19: 35 | F19: NE | G19: 7 | H19: 727
A20: Jan 1, 10:00 am | B20: 15 | C20: -3 | D20: 29 | F20: ENE | G20: 11 | H20: 726
A21: Jan 1, 11:00 am | B21: 16 | C21: -3 | D21: 26 | F21: ENE | G21: 9 | H21: 725
A22: Jan 1, 12:00 pm | B22: 18 | C22: -3 | D22: 24 | F22: NE | G22: 10 | H22: 724
A23: Jan 1, 1:00 pm | B23: 18 | C23: -3 | D23: 24 | F23: ENE | G23: 11 | H23: 723
A24: Jan 1, 2:00 pm | B24: 19 | C24: -3 | D24: 23 | F24: ENE | G24: 7 | H24: 722
A25: Jan 1, 3:00 pm | B25: 20 | C25: -3 | D25: 21 | F25: SE | G25: 6 | H25: 721
A26: Jan 1, 4:00 pm | B26: 20 | C26: -3 | D26: 21 | F26: SSE | G26: 3 | H26: 720
A27: Jan 1, 5:00 pm | B27: 18 | C27: -3 | D27: 24 | F27: ESE | G27: 9 | H27: 719
A28: Jan 1, 6:00 pm | B28: 14 | C28: -4 | D28: 29 | F28: N | G28: 2 | H28: 718
A29: Jan 1, 7:00 pm | B29: 10 | C29: -5 | D29: 35 | F29: NNE | G29: 3 | H29: 717
... A31: Jan 1, 9:00 pm | B31: 5 | C31: -6 | D31: 44 | F31: NE | G31: 1 | H31: 715
A32: Jan 1, 10:00 pm | B32: 6 | C32: -6 | D32: 40 | E32: 5 | F32: ENE | G32: 7 | H32: 714
A33: Jan 1, 11:00 pm | B33: 6 | C33: -7 | D33: 40 | F33: N | G33: 4 | H33: 713
A34: Jan 2, 12:00 am | B34: 6 | C34: -6 | D34: 41 | F34: NE | G34: 4 | H34: 712
A35: Jan 2, 1:00 am | B35: 7 | C35: -6 | D35: 39 | F35: NNE | G35: 5 | H35: 711
A36: Jan 2, 2:00 am | B36: 7 | C36: -6 | D36: 40 | F36: NNE | G36: 4 | H36: 710
A37: Jan 2, 3:00 am | B37: 8 | C37: -5 | D37: 38 | F37: N | G37: 2 | H37: 709
A38: Jan 2, 4:00 am | B38: 7 | C38: -6 | D38: 39 | F38: NE | G38: 5 | H38: 708
A39: Jan 2, 5:00 am | B39: 9 | C39: -6 | D39: 36 | F39: NNE | G39: 4 | H39: 707
A40: Jan 2, 6:00 am | B40: 13 | C40: -5 | D40: 29 | F40: ESE | G40: 8 | H40: 706
A41: Jan 2, 7:00 am | B41: 12 | C41: -5 | D41: 30 | F41: ESE | G41: 7 | H41: 705
...

Sheet Sayfa2
A1: Chart title
A2: DateTime | B2: Sütun3 | C2: Sütun2 | D2: Temperature | E2: Dew Point | F2: Relative Humidity
A3: 31.12.2024 | B3: 16 | C3: 00 | D3: 15.711 | E3: -1.72 | F3: 30.44
A4: 31.12.2024 | B4: 17 | C4: 00 | D4: 14.239 | E4: -1.12 | F4: 34.98
A5: 31.12.2024 | B5: 18 | C5: 00 | D5: 13.133 | E5: -1.13 | F5: 37.57
A6: 31.12.2024 | B6: 19 | C6: 00 | D6: 11.228 | E6: -2.42 | F6: 38.75
A7: 31.12.2024 | B7: 20 | C7: 00 | D7: 9.806 | E7: -3.02 | F7: 40.76
A8: 31.12.2024 | B8: 21 | C8: 00 | D8: 8.317 | E8: -4.45 | F8: 40.49
A9: 31.12.2024 | B9: 22 | C9: 00 | D9: 9.361 | E9: -4.3 | F9: 38.17
A10: 31.12.2024 | B10: 23 | C10: 00 | D10: 8.678 | E10: -4.29 | F10: 39.98
A11: 1.01.2025 | B11: 00 | C11: 00 | D11: 10.717 | E11: -4.06 | F11: 35.49
A12: 1.01.2025 | B12: 01 | C12: 00 | D12: 10.833 | E12: -4.67 | F12: 33.63
A13: 1.01.2025 | B13: 02 | C13: 00 | D13: 9.378 | E13: -5.41 | F13: 35.06
A14: 1.01.2025 | B14: 03 | C14: 00 | D14: 7.244 | E14: -5.59 | F14: 39.98
... A746: 31.01.2025 | B746: 15 | C746: 00 | D746: 16.35 | E746: 0.27 | F746: 33.77
